<?xml version="1.0" ?>
<robot name="spot" xmlns:xacro="http://www.ros.org/wiki/xacro">
    <link name="body">
        <visual>
            <geometry>
                <mesh filename="./meshes/body.dae" />
            </geometry>
        </visual>
        <collision>
            <geometry>
                <mesh filename="./meshes/body_collision.stl" />
            </geometry>
        </collision>
        <inertial>
            <mass value="14.40973585"/>
            <inertia ixx="0.1193931539" ixy="0.0" ixz="0.0" iyy="0.9617747728" iyz="0.0" izz="0.9876097355"/>
        </inertial>
    </link>

    <link name="base_link"/>
    <joint name="base_link_joint" type="fixed">
        <origin xyz="0 0 0" rpy="0 0 0" />
        <parent link="body" />
        <child link="base_link" />
    </joint>

    <link name="front_rail"/>
    <joint name="front_rail_joint" type="fixed">
        <origin xyz="0.223 0 0.0805" rpy="0 0 0" />
        <parent link="body" />
        <child link="front_rail" />
    </joint>

    <link name="rear_rail"/>
    <joint name="rear_rail_joint" type="fixed">
        <origin xyz="-0.223 0 0.0805" rpy="0 0 0" />
        <parent link="body" />
        <child link="rear_rail" />
    </joint>

    <link name="front_left_hip">
        <visual>
            <geometry>
                <mesh filename="./meshes/front_left_hip.dae" />
            </geometry>
        </visual>
        <collision>
            <geometry>
                <mesh filename="./meshes/front_left_hip_collision.stl" />
            </geometry>
        </collision>
        <inertial>
            <mass value="2.131962264"/>
            <inertia ixx="0.004840458991120049" ixy="1.9739042559750757e-06" ixz="-1.4537990385136328e-06" iyy="0.004164087201524784" iyz="1.2872309568206006e-06" izz="0.0042655393382746935"/>
        </inertial>
    </link>
    <joint name="front_left_hip_x" type="revolute">
        <origin xyz="0.29785 0.05500 0.00000" rpy="0 0.5235996938995747 0" />
        <axis xyz="1 0 0" />
        <parent link="body" />
        <child link="front_left_hip" />
        <limit effort="1000" velocity="1000.00" lower="-0.6" upper="0.5" />
    </joint>
    <link name="front_left_upper_leg">
        <visual>
            <geometry>
                <mesh filename="./meshes/front_left_upper_leg.dae" />
            </geometry>
        </visual>
        <collision>
            <geometry>
                <mesh filename="./meshes/front_left_upper_leg_collision.stl" />
            </geometry>
        </collision>
        <inertial>
            <mass value="0.934886792"/>
            <inertia ixx="0.09841956052568711" ixy="-0.035418844860068285" ixz="0.0239185221429445" iyy="0.06647528278171203" iyz="0.1012996403729267" izz="0.04470786622876792"/>
        </inertial>
    </link>
    <joint name="front_left_hip_y" type="revolute">
        <origin xyz="0.0 0.110945 0.0" rpy="0 0 0" />
        <axis xyz="0 1 0" />
        <parent link="front_left_hip" />
        <child link="front_left_upper_leg" />
        <limit effort="1000" velocity="1000.00" lower="-1.7" upper="1.7" />
    </joint>
    <link name="front_left_lower_leg">
        <visual>
            <geometry>
                <mesh filename="./meshes/front_left_lower_leg.dae" />
            </geometry>
        </visual>
        <collision>
            <geometry>
                <mesh filename="./meshes/front_left_lower_leg_collision.stl" />
            </geometry>
        </collision>
        <inertial>
            <mass value="0.137150943"/>
            <inertia ixx="0.026034033109202114" ixy="-6.558961855121463e-05" ixz="-6.107196767681762e-05" iyy="0.011480093961576602" iyz="-0.012746451515841613" izz="0.014652279026458286"/>
        </inertial>
    </link>
    <joint name="front_left_knee" type="revolute">
        <origin xyz="0.025 0.000 -0.3205" rpy="0 -1.1 0" />
        <axis xyz="0 1 0" />
        <parent link="front_left_upper_leg" />
        <child link="front_left_lower_leg" />
        <limit effort="1000" velocity="1000.00" lower="-0.45" upper="1.6" />
    </joint>
    <joint name="front_left_end" type="fixed">
        <parent link="front_left_lower_leg"/>
        <child link="front_left_contact"/>
        <origin xyz="0 0 -0.35" rpy="0 0 0"/>
    </joint>
    <link name="front_left_contact">
        <collision>
            <origin xyz="0 0 0" rpy="0 0 0"/>
            <geometry>
                <sphere radius="0.025"/>
            </geometry>
        </collision>
    </link>
    <link name="front_right_hip">
        <visual>
            <geometry>
                <mesh filename="./meshes/front_right_hip.dae" />
            </geometry>
        </visual>
        <collision>
            <geometry>
                <mesh filename="./meshes/front_right_hip_collision.stl" />
            </geometry>
        </collision>
        <inertial>
            <mass value="2.131962264"/>
            <inertia ixx="0.004840458991120049" ixy="-1.9737366790868247e-06" ixz="1.4537990385136328e-06" iyy="0.004164087201524784" iyz="1.2872309568206006e-06" izz="0.0042655393382746935"/>
        </inertial>
    </link>
    <joint name="front_right_hip_x" type="revolute">
        <origin xyz="0.29785 -0.05500 0.00000" rpy="0 0.5235996938995747 0" />
        <axis xyz="1 0 0" />
        <parent link="body" />
        <child link="front_right_hip" />
        <limit effort="1000" velocity="1000.00" lower="-0.6" upper="0.5" />
    </joint>
    <link name="front_right_upper_leg">
        <visual>
            <geometry>
                <mesh filename="./meshes/front_right_upper_leg.dae" />
            </geometry>
        </visual>
        <collision>
            <geometry>
                <mesh filename="./meshes/front_right_upper_leg_collision.stl" />
            </geometry>
        </collision>
        <inertial>
            <mass value="0.934886792"/>
            <inertia ixx="0.09841956052568711" ixy="0.03546126467713879" ixz="-0.02395093549986319" iyy="0.06647528278171203" iyz="0.04470786622876792" izz="0.1012996403729267"/>
        </inertial>
    </link>
    <joint name="front_right_hip_y" type="revolute">
        <origin xyz="0.0 -0.110945 0.0" rpy="0 0 0" />
        <axis xyz="0 1 0" />
        <parent link="front_right_hip" />
        <child link="front_right_upper_leg" />
        <limit effort="1000" velocity="1000.00" lower="-1.7" upper="1.7" />
    </joint>
    <link name="front_right_lower_leg">
        <visual>
            <geometry>
                <mesh filename="./meshes/front_right_lower_leg.dae" />
            </geometry>
        </visual>
        <collision>
            <geometry>
                <mesh filename="./meshes/front_right_lower_leg_collision.stl" />
            </geometry>
        </collision>
        <inertial>
            <mass value="0.137150943"/>
            <inertia ixx="0.026034033109202114" ixy="6.558985205280841e-05" ixz="6.107196767681762e-05" iyy="0.011480093961576602" iyz="-0.012746451515841613" izz="0.014652279026458286"/>
        </inertial>
    </link>
    <joint name="front_right_knee" type="revolute">
        <origin xyz="0.025 0.000 -0.3205" rpy="0 -1.1 0" />
        <axis xyz="0 1 0" />
        <parent link="front_right_upper_leg" />
        <child link="front_right_lower_leg" />
        <limit effort="1000" velocity="1000.00" lower="-0.45" upper="1.6" />
    </joint>
    <joint name="front_right_end" type="fixed">
        <parent link="front_right_lower_leg"/>
        <child link="front_right_contact"/>
        <origin xyz="0 0 -0.35" rpy="0 0 0"/>
    </joint>
    <link name="front_right_contact">
        <collision>
            <origin xyz="0 0 0" rpy="0 0 0"/>
            <geometry>
                <sphere radius="0.025"/>
            </geometry>
        </collision>
    </link>
    <link name="rear_left_hip">
        <visual>
            <geometry>
                <mesh filename="./meshes/rear_left_hip.dae" />
            </geometry>
        </visual>
        <collision>
            <geometry>
                <mesh filename="./meshes/rear_left_hip_collision.stl" />
            </geometry>
        </collision>
        <inertial>
            <mass value="2.131962264"/>
            <inertia ixx="0.004840458991120049" ixy="1.9739042559750757e-06" ixz="-1.4537990385136328e-06" iyy="0.004164087201524784" iyz="1.2872309568206006e-06" izz="0.0042655393382746935"/>
        </inertial>
    </link>
    <joint name="rear_left_hip_x" type="revolute">
        <origin xyz="-0.29785 0.05500 0.00000" rpy="0 0.5235996938995747 0" />
        <axis xyz="1 0 0" />
        <parent link="body" />
        <child link="rear_left_hip" />
        <limit effort="1000" velocity="1000.00" lower="-0.6" upper="0.5" />
    </joint>
    <link name="rear_left_upper_leg">
        <visual>
            <geometry>
                <mesh filename="./meshes/rear_left_upper_leg.dae" />
            </geometry>
        </visual>
        <collision>
            <geometry>
                <mesh filename="./meshes/rear_left_upper_leg_collision.stl" />
            </geometry>
        </collision>
        <inertial>
            <mass value="0.934886792"/>
            <inertia ixx="0.09841956052568711" ixy="-0.035418844860068285" ixz="0.0239185221429445" iyy="0.06647528278171203" iyz="0.1012996403729267" izz="0.04470786622876792"/>
        </inertial>
    </link>
    <joint name="rear_left_hip_y" type="revolute">
        <origin xyz="0.0 0.110945 0.0" rpy="0 0 0" />
        <axis xyz="0 1 0" />
        <parent link="rear_left_hip" />
        <child link="rear_left_upper_leg" />
        <limit effort="1000" velocity="1000.00" lower="-1.7" upper="1.7" />
    </joint>
    <link name="rear_left_lower_leg">
        <visual>
            <geometry>
                <mesh filename="./meshes/rear_left_lower_leg.dae" />
            </geometry>
        </visual>
        <collision>
            <geometry>
                <mesh filename="./meshes/rear_left_lower_leg_collision.stl" />
            </geometry>
        </collision>
        <inertial>
            <mass value="0.137150943"/>
            <inertia ixx="0.026034033109202114" ixy="-6.558961855121463e-05" ixz="-6.107196767681762e-05" iyy="0.011480093961576602" iyz="-0.012746451515841613" izz="0.014652279026458286"/>
        </inertial>
    </link>
    <joint name="rear_left_knee" type="revolute">
        <origin xyz="0.025 0.000 -0.3205" rpy="0 -1.1 0" />
        <axis xyz="0 1 0" />
        <parent link="rear_left_upper_leg" />
        <child link="rear_left_lower_leg" />
        <limit effort="1000" velocity="1000.00" lower="-0.45" upper="1.6" />
    </joint>
    <joint name="rear_left_end" type="fixed">
        <parent link="rear_left_lower_leg"/>
        <child link="rear_left_contact"/>
        <origin xyz="0 0 -0.35" rpy="0 0 0"/>
    </joint>
    <link name="rear_left_contact">
        <collision>
            <origin xyz="0 0 0" rpy="0 0 0"/>
            <geometry>
                <sphere radius="0.025"/>
            </geometry>
        </collision>
    </link>
    <link name="rear_right_hip">
        <visual>
            <geometry>
                <mesh filename="./meshes/rear_right_hip.dae" />
            </geometry>
        </visual>
        <collision>
            <geometry>
                <mesh filename="./meshes/rear_right_hip_collision.stl" />
            </geometry>
        </collision>
        <inertial>
            <mass value="2.131962264"/>
            <inertia ixx="0.004840458991120049" ixy="-1.9737366790868247e-06" ixz="1.4537990385136328e-06" iyy="0.004164087201524784" iyz="1.2872309568206006e-06" izz="0.0042655393382746935"/>
        </inertial>
    </link>
    <joint name="rear_right_hip_x" type="revolute">
        <origin xyz="-0.29785 -0.05500 0.00000" rpy="0 0.5235996938995747 0" />
        <axis xyz="1 0 0" />
        <parent link="body" />
        <child link="rear_right_hip" />
        <limit effort="1000" velocity="1000.00" lower="-0.6" upper="0.5" />
    </joint>
    <link name="rear_right_upper_leg">
        <visual>
            <geometry>
                <mesh filename="./meshes/rear_right_upper_leg.dae" />
            </geometry>
        </visual>
        <collision>
            <geometry>
                <mesh filename="./meshes/rear_right_upper_leg_collision.stl" />
            </geometry>
        </collision>
        <inertial>
            <mass value="0.934886792"/>
            <inertia ixx="0.09841956052568711" ixy="0.03546126467713879" ixz="-0.02395093549986319" iyy="0.06647528278171203" iyz="0.04470786622876792" izz="0.1012996403729267"/>
        </inertial>
    </link>
    <joint name="rear_right_hip_y" type="revolute">
        <origin xyz="0.0 -0.110945 0.0" rpy="0 0 0" />
        <axis xyz="0 1 0" />
        <parent link="rear_right_hip" />
        <child link="rear_right_upper_leg" />
        <limit effort="1000" velocity="1000.00" lower="-1.7" upper="1.7" />
    </joint>
    <link name="rear_right_lower_leg">
        <visual>
            <geometry>
                <mesh filename="./meshes/rear_right_lower_leg.dae" />
            </geometry>
        </visual>
        <collision>
            <geometry>
                <mesh filename="./meshes/rear_right_lower_leg_collision.stl" />
            </geometry>
        </collision>
        <inertial>
            <mass value="0.137150943"/>
            <inertia ixx="0.026034033109202114" ixy="6.558985205280841e-05" ixz="6.107196767681762e-05" iyy="0.011480093961576602" iyz="-0.012746451515841613" izz="0.014652279026458286"/>
        </inertial>
    </link>
    <joint name="rear_right_knee" type="revolute">
        <origin xyz="0.025 0.000 -0.3205" rpy="0 -1.1 0" />
        <axis xyz="0 1 0" />
        <parent link="rear_right_upper_leg" />
        <child link="rear_right_lower_leg" />
        <limit effort="1000" velocity="1000.00" lower="-0.45" upper="1.6" />
    </joint>
    <joint name="rear_right_end" type="fixed">
        <parent link="rear_right_lower_leg"/>
        <child link="rear_right_contact"/>
        <origin xyz="0 0 -0.35" rpy="0 0 0"/>
    </joint>
    <link name="rear_right_contact">
        <collision>
            <origin xyz="0 0 0" rpy="0 0 0"/>
            <geometry>
                <sphere radius="0.025"/>
            </geometry>
        </collision>
    </link>

    <!-- Optional custom includes. -->
    <xacro:include filename="$(optenv SPOT_URDF_EXTRAS empty.urdf)" />
</robot>
